<?xml version="1.0" encoding="UTF-8"?>
<testng-results retried="1" ignored="0" total="3" passed="1" failed="1" skipped="0">
  <reporter-output>
  </reporter-output>
  <suite started-at="2024-10-26T12:47:43 IST" name="Suite" finished-at="2024-10-26T12:48:11 IST" duration-ms="28187">
    <groups>
      <group name="purchase">
        <method signature="StandaloneTest.StandaloneTest(java.util.HashMap)[pri:0, instance:Practice.saucedemo.tests.StandaloneTest@34bde49d]" name="StandaloneTest" class="Practice.saucedemo.tests.StandaloneTest"/>
      </group> <!-- purchase -->
    </groups>
    <test started-at="2024-10-26T12:47:43 IST" name="Error validation Test" finished-at="2024-10-26T12:48:11 IST" duration-ms="28187">
      <class name="Practice.saucedemo.tests.ErrorValidation">
        <test-method is-config="true" signature="launchApplication()[pri:0, instance:Practice.saucedemo.tests.ErrorValidation@7c37508a]" started-at="2024-10-26T12:47:43 IST" name="launchApplication" finished-at="2024-10-26T12:47:52 IST" duration-ms="9733" status="PASS">
          <reporter-output>
          </reporter-output>
        </test-method> <!-- launchApplication -->
        <test-method signature="Productvalidation()[pri:0, instance:Practice.saucedemo.tests.ErrorValidation@7c37508a]" started-at="2024-10-26T12:47:52 IST" name="Productvalidation" finished-at="2024-10-26T12:47:54 IST" duration-ms="1792" status="PASS">
          <reporter-output>
          </reporter-output>
        </test-method> <!-- Productvalidation -->
        <test-method is-config="true" signature="tearDown()[pri:0, instance:Practice.saucedemo.tests.ErrorValidation@7c37508a]" started-at="2024-10-26T12:47:54 IST" name="tearDown" finished-at="2024-10-26T12:47:55 IST" duration-ms="1228" status="PASS">
          <reporter-output>
          </reporter-output>
        </test-method> <!-- tearDown -->
        <test-method is-config="true" signature="launchApplication()[pri:0, instance:Practice.saucedemo.tests.ErrorValidation@7c37508a]" started-at="2024-10-26T12:47:55 IST" name="launchApplication" finished-at="2024-10-26T12:48:02 IST" duration-ms="6699" status="PASS">
          <reporter-output>
          </reporter-output>
        </test-method> <!-- launchApplication -->
        <test-method retried="true" signature="StandaloneTest()[pri:0, instance:Practice.saucedemo.tests.ErrorValidation@7c37508a]" started-at="2024-10-26T12:48:02 IST" name="StandaloneTest" finished-at="2024-10-26T12:48:03 IST" duration-ms="448" status="SKIP">
          <exception class="java.lang.AssertionError">
            <message>
              <![CDATA[expected [Epic sadface: Username and password do not match any user in this service] but found [ Username and password do not match any user in this service]]]>
            </message>
            <full-stacktrace>
              <![CDATA[java.lang.AssertionError: expected [Epic sadface: Username and password do not match any user in this service] but found [ Username and password do not match any user in this service]
at org.testng.Assert.fail(Assert.java:110)
at org.testng.Assert.failNotEquals(Assert.java:1577)
at org.testng.Assert.assertEqualsImpl(Assert.java:149)
at org.testng.Assert.assertEquals(Assert.java:131)
at org.testng.Assert.assertEquals(Assert.java:655)
at org.testng.Assert.assertEquals(Assert.java:665)
at Practice.saucedemo.tests.ErrorValidation.StandaloneTest(ErrorValidation.java:27)
at java.base/jdk.internal.reflect.DirectMethodHandleAccessor.invoke(DirectMethodHandleAccessor.java:103)
at java.base/java.lang.reflect.Method.invoke(Method.java:580)
at org.testng.internal.invokers.MethodInvocationHelper.invokeMethod(MethodInvocationHelper.java:139)
at org.testng.internal.invokers.TestInvoker.invokeMethod(TestInvoker.java:677)
at org.testng.internal.invokers.TestInvoker.invokeTestMethod(TestInvoker.java:221)
at org.testng.internal.invokers.MethodRunner.runInSequence(MethodRunner.java:50)
at org.testng.internal.invokers.TestInvoker$MethodInvocationAgent.invoke(TestInvoker.java:969)
at org.testng.internal.invokers.TestInvoker.invokeTestMethods(TestInvoker.java:194)
at org.testng.internal.invokers.TestMethodWorker.invokeTestMethods(TestMethodWorker.java:148)
at org.testng.internal.invokers.TestMethodWorker.run(TestMethodWorker.java:128)
at java.base/java.util.ArrayList.forEach(ArrayList.java:1596)
at org.testng.TestRunner.privateRun(TestRunner.java:829)
at org.testng.TestRunner.run(TestRunner.java:602)
at org.testng.SuiteRunner.runTest(SuiteRunner.java:437)
at org.testng.SuiteRunner$SuiteWorker.run(SuiteRunner.java:475)
at org.testng.internal.thread.ThreadUtil.lambda$execute$0(ThreadUtil.java:58)
at java.base/java.util.concurrent.FutureTask.run(FutureTask.java:317)
at java.base/java.util.concurrent.ThreadPoolExecutor.runWorker(ThreadPoolExecutor.java:1144)
at java.base/java.util.concurrent.ThreadPoolExecutor$Worker.run(ThreadPoolExecutor.java:642)
at java.base/java.lang.Thread.run(Thread.java:1583)
]]>
            </full-stacktrace>
          </exception> <!-- java.lang.AssertionError -->
          <reporter-output>
          </reporter-output>
        </test-method> <!-- StandaloneTest -->
        <test-method is-config="true" signature="tearDown()[pri:0, instance:Practice.saucedemo.tests.ErrorValidation@7c37508a]" started-at="2024-10-26T12:48:03 IST" name="tearDown" finished-at="2024-10-26T12:48:04 IST" duration-ms="1042" status="PASS">
          <reporter-output>
          </reporter-output>
        </test-method> <!-- tearDown -->
        <test-method is-config="true" signature="launchApplication()[pri:0, instance:Practice.saucedemo.tests.ErrorValidation@7c37508a]" started-at="2024-10-26T12:48:04 IST" name="launchApplication" finished-at="2024-10-26T12:48:09 IST" duration-ms="5890" status="PASS">
          <reporter-output>
          </reporter-output>
        </test-method> <!-- launchApplication -->
        <test-method signature="StandaloneTest()[pri:0, instance:Practice.saucedemo.tests.ErrorValidation@7c37508a]" started-at="2024-10-26T12:48:09 IST" name="StandaloneTest" finished-at="2024-10-26T12:48:10 IST" duration-ms="401" status="FAIL">
          <exception class="java.lang.AssertionError">
            <message>
              <![CDATA[expected [Epic sadface: Username and password do not match any user in this service] but found [ Username and password do not match any user in this service]]]>
            </message>
            <full-stacktrace>
              <![CDATA[java.lang.AssertionError: expected [Epic sadface: Username and password do not match any user in this service] but found [ Username and password do not match any user in this service]
at org.testng.Assert.fail(Assert.java:110)
at org.testng.Assert.failNotEquals(Assert.java:1577)
at org.testng.Assert.assertEqualsImpl(Assert.java:149)
at org.testng.Assert.assertEquals(Assert.java:131)
at org.testng.Assert.assertEquals(Assert.java:655)
at org.testng.Assert.assertEquals(Assert.java:665)
at Practice.saucedemo.tests.ErrorValidation.StandaloneTest(ErrorValidation.java:27)
at java.base/jdk.internal.reflect.DirectMethodHandleAccessor.invoke(DirectMethodHandleAccessor.java:103)
at java.base/java.lang.reflect.Method.invoke(Method.java:580)
at org.testng.internal.invokers.MethodInvocationHelper.invokeMethod(MethodInvocationHelper.java:139)
at org.testng.internal.invokers.TestInvoker.invokeMethod(TestInvoker.java:677)
at org.testng.internal.invokers.TestInvoker.retryFailed(TestInvoker.java:263)
at org.testng.internal.invokers.MethodRunner.runInSequence(MethodRunner.java:62)
at org.testng.internal.invokers.TestInvoker$MethodInvocationAgent.invoke(TestInvoker.java:969)
at org.testng.internal.invokers.TestInvoker.invokeTestMethods(TestInvoker.java:194)
at org.testng.internal.invokers.TestMethodWorker.invokeTestMethods(TestMethodWorker.java:148)
at org.testng.internal.invokers.TestMethodWorker.run(TestMethodWorker.java:128)
at java.base/java.util.ArrayList.forEach(ArrayList.java:1596)
at org.testng.TestRunner.privateRun(TestRunner.java:829)
at org.testng.TestRunner.run(TestRunner.java:602)
at org.testng.SuiteRunner.runTest(SuiteRunner.java:437)
at org.testng.SuiteRunner$SuiteWorker.run(SuiteRunner.java:475)
at org.testng.internal.thread.ThreadUtil.lambda$execute$0(ThreadUtil.java:58)
at java.base/java.util.concurrent.FutureTask.run(FutureTask.java:317)
at java.base/java.util.concurrent.ThreadPoolExecutor.runWorker(ThreadPoolExecutor.java:1144)
at java.base/java.util.concurrent.ThreadPoolExecutor$Worker.run(ThreadPoolExecutor.java:642)
at java.base/java.lang.Thread.run(Thread.java:1583)
]]>
            </full-stacktrace>
          </exception> <!-- java.lang.AssertionError -->
          <reporter-output>
          </reporter-output>
        </test-method> <!-- StandaloneTest -->
        <test-method is-config="true" signature="tearDown()[pri:0, instance:Practice.saucedemo.tests.ErrorValidation@7c37508a]" started-at="2024-10-26T12:48:10 IST" name="tearDown" finished-at="2024-10-26T12:48:11 IST" duration-ms="799" status="PASS">
          <reporter-output>
          </reporter-output>
        </test-method> <!-- tearDown -->
      </class> <!-- Practice.saucedemo.tests.ErrorValidation -->
    </test> <!-- Error validation Test -->
  </suite> <!-- Suite -->
</testng-results>
