<?xml version="1.0" encoding="UTF-8"?>
<testng-results ignored="0" total="2" passed="1" failed="1" skipped="0">
  <reporter-output>
  </reporter-output>
  <suite started-at="2024-09-01T18:29:02 IST" name="Suite" finished-at="2024-09-01T18:29:14 IST" duration-ms="12788">
    <groups>
      <group name="purchase">
        <method signature="StandaloneTest.StandaloneTest(java.util.HashMap)[pri:0, instance:Practice.saucedemo.tests.StandaloneTest@6995bf68]" name="StandaloneTest" class="Practice.saucedemo.tests.StandaloneTest"/>
      </group> <!-- purchase -->
    </groups>
    <test started-at="2024-09-01T18:29:02 IST" name="Error validation Test" finished-at="2024-09-01T18:29:14 IST" duration-ms="12788">
      <class name="Practice.saucedemo.tests.ErrorValidation">
        <test-method is-config="true" signature="launchApplication()[pri:0, instance:Practice.saucedemo.tests.ErrorValidation@3d3e5463]" started-at="2024-09-01T18:29:02 IST" name="launchApplication" finished-at="2024-09-01T18:29:09 IST" duration-ms="7219" status="PASS">
          <reporter-output>
          </reporter-output>
        </test-method> <!-- launchApplication -->
        <test-method signature="Productvalidation()[pri:0, instance:Practice.saucedemo.tests.ErrorValidation@3d3e5463]" started-at="2024-09-01T18:29:09 IST" name="Productvalidation" finished-at="2024-09-01T18:29:10 IST" duration-ms="1130" status="PASS">
          <reporter-output>
          </reporter-output>
        </test-method> <!-- Productvalidation -->
        <test-method is-config="true" signature="tearDown()[pri:0, instance:Practice.saucedemo.tests.ErrorValidation@3d3e5463]" started-at="2024-09-01T18:29:10 IST" name="tearDown" finished-at="2024-09-01T18:29:10 IST" duration-ms="176" status="PASS">
          <reporter-output>
          </reporter-output>
        </test-method> <!-- tearDown -->
        <test-method is-config="true" signature="launchApplication()[pri:0, instance:Practice.saucedemo.tests.ErrorValidation@3d3e5463]" started-at="2024-09-01T18:29:10 IST" name="launchApplication" finished-at="2024-09-01T18:29:13 IST" duration-ms="3089" status="PASS">
          <reporter-output>
          </reporter-output>
        </test-method> <!-- launchApplication -->
        <test-method signature="StandaloneTest()[pri:0, instance:Practice.saucedemo.tests.ErrorValidation@3d3e5463]" started-at="2024-09-01T18:29:13 IST" name="StandaloneTest" finished-at="2024-09-01T18:29:14 IST" duration-ms="618" status="FAIL">
          <exception class="java.lang.AssertionError">
            <message>
              <![CDATA[expected [Epic sadface: Username and password do not match any user in this service] but found [ Username and password do not match any user in this service]]]>
            </message>
            <full-stacktrace>
              <![CDATA[java.lang.AssertionError: expected [Epic sadface: Username and password do not match any user in this service] but found [ Username and password do not match any user in this service]
at org.testng.Assert.fail(Assert.java:110)
at org.testng.Assert.failNotEquals(Assert.java:1577)
at org.testng.Assert.assertEqualsImpl(Assert.java:149)
at org.testng.Assert.assertEquals(Assert.java:131)
at org.testng.Assert.assertEquals(Assert.java:655)
at org.testng.Assert.assertEquals(Assert.java:665)
at Practice.saucedemo.tests.ErrorValidation.StandaloneTest(ErrorValidation.java:27)
at java.base/jdk.internal.reflect.NativeMethodAccessorImpl.invoke0(Native Method)
at java.base/jdk.internal.reflect.NativeMethodAccessorImpl.invoke(NativeMethodAccessorImpl.java:77)
at java.base/jdk.internal.reflect.DelegatingMethodAccessorImpl.invoke(DelegatingMethodAccessorImpl.java:43)
at java.base/java.lang.reflect.Method.invoke(Method.java:568)
at org.testng.internal.invokers.MethodInvocationHelper.invokeMethod(MethodInvocationHelper.java:139)
at org.testng.internal.invokers.TestInvoker.invokeMethod(TestInvoker.java:677)
at org.testng.internal.invokers.TestInvoker.invokeTestMethod(TestInvoker.java:221)
at org.testng.internal.invokers.MethodRunner.runInSequence(MethodRunner.java:50)
at org.testng.internal.invokers.TestInvoker$MethodInvocationAgent.invoke(TestInvoker.java:969)
at org.testng.internal.invokers.TestInvoker.invokeTestMethods(TestInvoker.java:194)
at org.testng.internal.invokers.TestMethodWorker.invokeTestMethods(TestMethodWorker.java:148)
at org.testng.internal.invokers.TestMethodWorker.run(TestMethodWorker.java:128)
at java.base/java.util.ArrayList.forEach(ArrayList.java:1511)
at org.testng.TestRunner.privateRun(TestRunner.java:829)
at org.testng.TestRunner.run(TestRunner.java:602)
at org.testng.SuiteRunner.runTest(SuiteRunner.java:437)
at org.testng.SuiteRunner$SuiteWorker.run(SuiteRunner.java:475)
at org.testng.internal.thread.ThreadUtil.lambda$execute$0(ThreadUtil.java:58)
at java.base/java.util.concurrent.FutureTask.run(FutureTask.java:264)
at java.base/java.util.concurrent.ThreadPoolExecutor.runWorker(ThreadPoolExecutor.java:1136)
at java.base/java.util.concurrent.ThreadPoolExecutor$Worker.run(ThreadPoolExecutor.java:635)
at java.base/java.lang.Thread.run(Thread.java:833)
]]>
            </full-stacktrace>
          </exception> <!-- java.lang.AssertionError -->
          <reporter-output>
          </reporter-output>
        </test-method> <!-- StandaloneTest -->
        <test-method is-config="true" signature="tearDown()[pri:0, instance:Practice.saucedemo.tests.ErrorValidation@3d3e5463]" started-at="2024-09-01T18:29:14 IST" name="tearDown" finished-at="2024-09-01T18:29:14 IST" duration-ms="219" status="PASS">
          <reporter-output>
          </reporter-output>
        </test-method> <!-- tearDown -->
      </class> <!-- Practice.saucedemo.tests.ErrorValidation -->
    </test> <!-- Error validation Test -->
  </suite> <!-- Suite -->
</testng-results>
